Workbook

Sheet Overview
A1: FIFA World Cup 2026 – Dashboard Guide
A2: Companion workbook to the Power BI report FIFA_WC2026.pbip | Simulated data, not official FIFA results
A4: Purpose | B4: Explains every page, visual and DAX measure of the Power BI dashboard, documents the data model and data-quality decisions, and shows that the dashboard numbers were checked independently.
A5: Data source | B5: https://www.kaggle.com/datasets/rauffauzanrambe/fifa-world-cup-2026-player-performance-dataset
A6: Dataset | B6: 54,600 rows × 75 columns – one row per player per match (1,248 players, 48 teams, 1,050 matches, 16 stadiums)
A8: Headline numbers
A9: KPI | B9: Value | C9: How it is calculated (formula reads the other sheets)
A10: Matches | B10: =SUM(Teams!C5:C52)/2 -> 1050 | C10: Each match appears twice in the Teams sheet (once per team)
A11: Total goals | B11: =SUM(Teams!G5:G52) -> 2794 | C11: Official match scores (goals_team), not the sum of player goals
A12: Goals per match | B12: =B11/B10 -> 2.6609524 | C12: Total goals ÷ matches
A13: Players used | B13: =COUNTIF(Players!G5:G1252,">0") -> 1248 | C13: Players with at least one appearance
A14: Average player rating | B14: =SUMPRODUCT(Players!G5:G1252,Players!J5:J1252)/SUM(Players!G5:G1252) -> 6.2885671 | C14: Weighted by appearances – unused substitutes (rating 0) excluded
A15: Draw rate | B15: =SUM(Teams!E5:E52)/2/B10 -> 0.26285714 | C15: Drawn matches ÷ matches
A16: Value vs rating correlation | B16: =Players!$N$2 -> 0.73071391 | C16: Pearson r, qualified players only (see Players sheet)
A18: Sheets in this workbook
A19: Sheet | C19: What it contains
A20: Screenshots | C20: The six dashboard pages
A21: Pages Guide | C21: Every visual: what question it answers, which fields and measures it uses, how to interact
A22: Key Insights | C22: The six business questions and the answers the data gives
A23: Teams | C23: 48 teams: results and per-match rates (formulas)
A24: Players | C24: 1,248 players: value-for-money percentiles and the correlation, recalculated with Excel formulas
A25: Positions | C25: Position profile used on the Players page (formulas)
A26: Measures | C26: All 101 DAX measures with folder, format, description and full DAX code
A27: Data Model | C27: Tables, grain, row counts and relationships of the star schema
A28: Data Quality | C28: Problems found in the raw file and how each was handled
A29: QA Reconciliation | C29: 97 dashboard numbers checked against an independent Python calculation
A31: How to open the dashboard
A32: 1. Open FIFA_WC2026.pbip in Power BI Desktop (2025 or later).
A33: 2. Transform data → Edit parameters → CsvFilePath: paste the full path to the CSV file.
A34: 3. Click Refresh.

Sheet Screenshots
A1: Dashboard pages
A2: Exported from Power BI Desktop
A4: Overview
A34: Teams
A64: Players
A94: Physical
A124: Compare
A154: Player Profile

Sheet Pages Guide
A1: Pages guide
A2: Every visual on the dashboard, the question it answers and what drives it
A4: Page | B4: Visual | C4: Type | D4: Question it answers | E4: Fields / measures | F4: How to read or use it
A5: Overview | B5: Slicers: Stage, Confederation, Team, Position | C5: Dropdown slicers | D5: Which part of the tournament am I looking at? | E5: Dim_Match[tournament_stage], Dim_Team[Confederation], Dim_Team[team], Dim_Player[position] | F5: Filter every visual on the page. Position affects player measures only (team results are not filtered by position).
A6: Overview | B6: KPI cards | C6: Cards | D6: How big was the tournament and how did it play? | E6: Matches, Total Goals, Goals per Match, Players Used, Avg Player Rating, Draw Rate | F6: Total Goals uses the official match score; Avg Player Rating counts only players who played.
A7: Overview | B7: Goals per match by stage | C7: Column chart | D7: Does scoring change as the tournament goes on? | E7: Dim_Match[tournament_stage] × Goals per Match (tooltip: Matches) | F7: Later stages have very few matches; hover to see the sample size before drawing conclusions.
A8: Overview | B8: Top 10 scorers | C8: Bar chart | D8: Who scored the most? | E8: Dim_Player[Player Label] × Goals, Top N = 10 by Scorer Rank Value | F8: Ties are broken by assists, then goals per 90, so exactly ten players show.
A9: Overview | B9: Matches by host city | C9: Bar chart | D9: Where were matches played? | E9: Dim_Stadium[city] × Matches (tooltip: Goals per Match) | F9: Workload per host city.
A10: Teams | B10: Slicers: Stage, Group / Knockout, Confederation | C10: Dropdown slicers | D10: Which matches? | E10: Dim_Match, Dim_Team
A11: Teams | B11: Team results | C11: Table | D11: Which teams perform best? | E11: MP, W, D, L, Win %, Pts/M, GF/M, GA/M, GD, xG/M | F11: Sorted by Win %. Teams played 33–66 matches, so compare the rates, not totals.
A12: Teams | B12: Goals vs xG per match | C12: Scatter | D12: Do teams score more or less than their chances suggest? | E12: Dim_Team[Team Code]; X = Team xG per Match; Y = Goals For per Match | F12: Dashed lines are the tournament averages (0.42 xG, 1.33 goals). Top-right = creates and scores a lot.
A13: Teams | B13: Win % by confederation | C13: Bar chart | D13: Does any confederation dominate? | E13: Dim_Team[Confederation] × Win % | F13: All confederations are within 34.6%–38.4%.
A14: Players | B14: Slicers: Position, Team, Market value band, Min. minutes | C14: Dropdown slicers | D14: Which players are compared? | E14: Dim_Player, Dim_Team, Param_MinMinutes | F14: Min. minutes (default 900) removes small samples from the scatter and the value table.
A15: Players | B15: Value-rating correlation | C15: Card | D15: Does price predict performance? | E15: Value vs Rating Correlation | F15: Pearson r; 0.73 = strong positive link.
A16: Players | B16: Market value vs average rating | C16: Scatter (log X axis) | D16: Is the most expensive player the best? | E16: Dim_Player[Player Label]; Series = position; X = Qualified Market Value (EUR M); Y = Qualified Avg Rating | F16: Points above the cloud at a given price are players who outperform their value.
A17: Players | B17: Best value for money | C17: Table | D17: Who are the bargains? | E17: Market Value (EUR M), Avg Player Rating, Rating Percentile, Value Percentile, Bargain Gap | F17: Gap = rating percentile − value percentile. +56% means the player ranks 56 points higher on rating than on price.
A18: Players | B18: Position profile | C18: Table | D18: How do positions differ? | E18: Players Used, Avg Player Rating, Goal Contributions per 90, Key Passes per 90, Defensive Actions per 90, Pass Accuracy %
A19: Physical | B19: Slicers: Position, Age group, Team, Confederation | C19: Dropdown slicers | E19: Dim_Player, Dim_Team
A20: Physical | B20: KPI cards | C20: Cards | D20: What is the physical load? | E20: Distance per 90, Sprint Distance per 90, Avg Top Speed, Max Top Speed, Avg Stamina Score | F20: Per-90 values make players with different minutes comparable.
A21: Physical | B21: Distance per 90 by position | C21: Column chart | D21: Who runs the most? | E21: Dim_Player[position] × Distance and Sprint Distance per 90 | F21: Midfielders lead (10.8 km).
A22: Physical | B22: Top speed by position | C22: Column chart | D22: Who is fastest? | E22: Dim_Player[position] × Avg Top Speed (km/h) | F22: Goalkeepers 29.0; all outfield positions 32.5.
A23: Physical | B23: Stamina by age | C23: Line chart (axis 0–100) | D23: Does stamina fall with age? | E23: Dim_Player[age] × Avg Stamina Score | F23: The full 0–100 axis shows honestly that the line is almost flat. Ages 37+ are only 6 players.
A24: Compare | B24: Player A / Player B slicers | C24: Searchable dropdowns | D24: Which two players? | E24: Compare_Player_A[Player A], Compare_Player_B[Player B] | F24: Disconnected tables, so the two choices do not filter each other.
A25: Compare | B25: Share of each metric | C25: 100% stacked bar | D25: Who is stronger on each metric? | E25: Comparison_Metrics[Metric] × Player A Value, Player B Value | F25: Gold = Player A, blue = Player B. Shows 18 performance metrics.
A26: Compare | B26: Head-to-head | C26: Table | D26: Exact numbers side by side | E26: Player A Value, Edge Label, Player B Value | F26: Better column shows A, B or = using the values as displayed. Formats switch automatically (dynamic format string).
A27: Player Profile | B27: Player slicer | C27: Searchable dropdown | D27: Which player? | E27: Dim_Player[Player Label] | F27: Single selection, default Memphis Zerrouki.
A28: Player Profile | B28: Name and info line | C28: Cards | D28: Who is the player? | E28: Selected Player, Player Info | F28: Team | position | age | club | height | foot.
A29: Player Profile | B29: KPI cards | C29: Cards | D29: Headline output | E29: Appearances, Minutes Played, Goals, Assists, Avg Player Rating, Market Value (EUR M)
A30: Player Profile | B30: Player vs position average | C30: Table | D30: Is the player above or below his position? | E30: Metric Value, Position Avg Value, Vs Position Avg % | F30: Rates are pooled for the position; totals are averaged per player.
A31: Player Profile | B31: Match rating | C31: Line chart | D31: How consistent is the player? | E31: Dim_Date[Date] × Avg Player Rating
A32: Player Profile | B32: Goals and assists by stage | C32: Column chart | D32: When does the player contribute? | E32: Dim_Match[tournament_stage] × Goals, Assists

Sheet Key Insights
A1: Key insights
A2: Six business questions answered by the dashboard
A4: # | B4: Question | C4: Answer | D4: Where on the dashboard
A5: 1 | B5: How many goals per match, and does it change by stage? | C5: 2.66 goals per match over 1,050 matches (2,794 goals). Stages range from 2.29 (third-place match) to 3.00 (semi-finals and final), but knockout stages have very few matches (21 finals vs 578 group games), so the differences are not meaningful. | D5: Overview
A6: 2 | B6: Which teams perform best? | C6: Nigeria has the highest win rate (57.5%, 23 wins in 40 matches) and the best goal difference (+26). Morocco concedes the fewest goals per match (0.98). Confederations are within 34.6%–38.4% win rate, so none dominates. | D6: Teams
A7: 3 | B7: Who are the best scorers? | C7: Memphis Zerrouki (Netherlands) leads with 24 goals; Mohannad Majeed (Iraq) matches his rate (0.97 goals per 90) in fewer minutes. | D7: Overview, Compare
A8: 4 | B8: Is the most expensive player the best? | C8: Largely yes: correlation between market value and average rating is r = 0.73 (players with 900+ minutes). The exceptions are the story: Marcus Mount (England, defender, €1.0M) out-rates 57% of qualified players; Themba Xoki (South Africa, €7.9M) is in the 91st rating percentile. | D8: Players
A9: 5 | B9: How do positions differ? | C9: Forwards have the highest rating (6.36) and goal contributions (0.53 per 90). Midfielders cover the most ground (10.8 km per 90) and pass most accurately (83.7%). Defenders make 10.9 defensive actions per 90. | D9: Players, Physical
A10: 6 | B10: Does physical performance drop with age? | C10: No. Stamina is almost flat (87.4 for 21 and under vs 86.8 for 34+). Top speed is identical for all outfield positions (32.5 km/h). | D10: Physical

Sheet Teams
A1: Teams
A2: Inputs from the data (black) and per-match rates (formulas). Sorted by win %.
A4: Team | B4: Confederation | C4: MP | D4: W | E4: D | F4: L | G4: GF | H4: GA | I4: Team xG | J4: Win % | K4: Points | L4: Pts/M | M4: GF/M | N4: GA/M | O4: GD | P4: xG/M
A5: Nigeria | B5: CAF | C5: 40 | D5: 23 | E5: 10 | F5: 7 | G5: 68 | H5: 42 | I5: 15.24 | J5: =D5/C5 -> 0.575 | K5: =3*D5+E5 -> 79 | L5: =K5/C5 -> 1.975 | M5: =G5/C5 -> 1.7 | N5: =H5/C5 -> 1.05 | O5: =G5-H5 -> 26 | P5: =I5/C5 -> 0.381
A6: Colombia | B6: CONMEBOL | C6: 46 | D6: 24 | E6: 4 | F6: 18 | G6: 66 | H6: 61 | I6: 18.68 | J6: =D6/C6 -> 0.52173913 | K6: =3*D6+E6 -> 76 | L6: =K6/C6 -> 1.6521739 | M6: =G6/C6 -> 1.4347826 | N6: =H6/C6 -> 1.326087 | O6: =G6-H6 -> 5 | P6: =I6/C6 -> 0.40608696
A7: Brazil | B7: CONMEBOL | C7: 45 | D7: 22 | E7: 11 | F7: 12 | G7: 73 | H7: 53 | I7: 19.34 | J7: =D7/C7 -> 0.48888889 | K7: =3*D7+E7 -> 77 | L7: =K7/C7 -> 1.7111111 | M7: =G7/C7 -> 1.6222222 | N7: =H7/C7 -> 1.1777778 | O7: =G7-H7 -> 20 | P7: =I7/C7 -> 0.42977778
A8: Portugal | B8: UEFA | C8: 43 | D8: 21 | E8: 9 | F8: 13 | G8: 63 | H8: 57 | I8: 16.75 | J8: =D8/C8 -> 0.48837209 | K8: =3*D8+E8 -> 72 | L8: =K8/C8 -> 1.6744186 | M8: =G8/C8 -> 1.4651163 | N8: =H8/C8 -> 1.3255814 | O8: =G8-H8 -> 6 | P8: =I8/C8 -> 0.38953488
A9: Belgium | B9: UEFA | C9: 51 | D9: 24 | E9: 11 | F9: 16 | G9: 79 | H9: 70 | I9: 27.41 | J9: =D9/C9 -> 0.47058824 | K9: =3*D9+E9 -> 83 | L9: =K9/C9 -> 1.627451 | M9: =G9/C9 -> 1.5490196 | N9: =H9/C9 -> 1.372549 | O9: =G9-H9 -> 9 | P9: =I9/C9 -> 0.53745098
A10: Algeria | B10: CAF | C10: 41 | D10: 19 | E10: 7 | F10: 15 | G10: 60 | H10: 51 | I10: 17.32 | J10: =D10/C10 -> 0.46341463 | K10: =3*D10+E10 -> 64 | L10: =K10/C10 -> 1.5609756 | M10: =G10/C10 -> 1.4634146 | N10: =H10/C10 -> 1.2439024 | O10: =G10-H10 -> 9 | P10: =I10/C10 -> 0.42243902
A11: Jamaica | B11: CONCACAF | C11: 59 | D11: 27 | E11: 9 | F11: 23 | G11: 88 | H11: 80 | I11: 20.7 | J11: =D11/C11 -> 0.45762712 | K11: =3*D11+E11 -> 90 | L11: =K11/C11 -> 1.5254237 | M11: =G11/C11 -> 1.4915254 | N11: =H11/C11 -> 1.3559322 | O11: =G11-H11 -> 8 | P11: =I11/C11 -> 0.35084746
A12: England | B12: UEFA | C12: 44 | D12: 20 | E12: 12 | F12: 12 | G12: 61 | H12: 53 | I12: 20.99 | J12: =D12/C12 -> 0.45454545 | K12: =3*D12+E12 -> 72 | L12: =K12/C12 -> 1.6363636 | M12: =G12/C12 -> 1.3863636 | N12: =H12/C12 -> 1.2045455 | O12: =G12-H12 -> 8 | P12: =I12/C12 -> 0.47704545
A13: Japan | B13: AFC | C13: 36 | D13: 16 | E13: 7 | F13: 13 | G13: 50 | H13: 40 | I13: 13.33 | J13: =D13/C13 -> 0.44444444 | K13: =3*D13+E13 -> 55 | L13: =K13/C13 -> 1.5277778 | M13: =G13/C13 -> 1.3888889 | N13: =H13/C13 -> 1.1111111 | O13: =G13-H13 -> 10 | P13: =I13/C13 -> 0.37027778
A14: Morocco | B14: CAF | C14: 55 | D14: 24 | E14: 16 | F14: 15 | G14: 78 | H14: 54 | I14: 25.47 | J14: =D14/C14 -> 0.43636364 | K14: =3*D14+E14 -> 88 | L14: =K14/C14 -> 1.6 | M14: =G14/C14 -> 1.4181818 | N14: =H14/C14 -> 0.98181818 | O14: =G14-H14 -> 24 | P14: =I14/C14 -> 0.46309091
A15: Poland | B15: UEFA | C15: 39 | D15: 17 | E15: 10 | F15: 12 | G15: 60 | H15: 45 | I15: 15.13 | J15: =D15/C15 -> 0.43589744 | K15: =3*D15+E15 -> 61 | L15: =K15/C15 -> 1.5641026 | M15: =G15/C15 -> 1.5384615 | N15: =H15/C15 -> 1.1538462 | O15: =G15-H15 -> 15 | P15: =I15/C15 -> 0.38794872
A16: Turkey | B16: UEFA | C16: 50 | D16: 21 | E16: 13 | F16: 16 | G16: 70 | H16: 69 | I16: 21.26 | J16: =D16/C16 -> 0.42 | K16: =3*D16+E16 -> 76 | L16: =K16/C16 -> 1.52 | M16: =G16/C16 -> 1.4 | N16: =H16/C16 -> 1.38 | O16: =G16-H16 -> 1 | P16: =I16/C16 -> 0.4252
... A52: Ukraine | B52: UEFA | C52: 38 | D52: 7 | E52: 11 | F52: 20 | G52: 39 | H52: 70 | I52: 13.74 | J52: =D52/C52 -> 0.18421053 | K52: =3*D52+E52 -> 32 | L52: =K52/C52 -> 0.84210526 | M52: =G52/C52 -> 1.0263158 | N52: =H52/C52 -> 1.8421053 | O52: =G52-H52 -> -31 | P52: =I52/C52 -> 0.36157895
A54: Check: total team-matches | C54: =SUM(C5:C52) -> 2100
A55: Check: wins = losses | C55: =IF(SUM(D5:D52)=SUM(F5:F52),"OK","CHECK") -> OK

Sheet Players
A1: Players – value for money | M1: Min. minutes (input) | N1: 900
A2: Percentiles and correlation recalculated with Excel formulas. Change the blue input to test another threshold. | M2: Value vs rating r | N2: =CORREL(O5:O1252,P5:P1252) -> 0.73071391
A3: Rows are sorted by bargain gap at the default 900 minutes; if you change the input, sort column N again. | M3: Qualified players | N3: =SUM(K5:K1252) -> 1208
A4: Player | B4: Team | C4: Position | D4: Age | E4: Market value (EUR M) | F4: Minutes | G4: Appearances | H4: Goals | I4: Assists | J4: Avg rating | K4: Qualified | L4: Rating pct | M4: Value pct | N4: Bargain gap | O4: X (qualified value) | P4: Y (qualified rating)
A5: Marcus Mount | B5: England | C5: Defender | D5: 30 | E5: 1.029642 | F5: 1731 | G5: 30 | H5: 0 | I5: 1 | J5: 6.27 | K5: =IF(F5>=$N$1,1,0) -> 1 | L5: =IF(K5=1,COUNTIFS($K$5:$K$1252,1,$J$5:$J$1252,"<"&J5)/($N$3-1),"") -> 0.56669428 | M5: =IF(K5=1,COUNTIFS($K$5:$K$1252,1,$E$5:$E$1252,"<"&E5)/($N$3-1),"") -> 0.0066280033 | N5: =IF(K5=1,L5-M5,"") -> 0.56006628 | O5: =IF(K5=1,E5,"") -> 1.029642 | P5: =IF(K5=1,J5,"") -> 6.27
A6: Themba Xoki | B6: South Africa | C6: Forward | D6: 24 | E6: 7.907726 | F6: 1586 | G6: 23 | H6: 13 | I6: 2 | J6: 6.9478261 | K6: =IF(F6>=$N$1,1,0) -> 1 | L6: =IF(K6=1,COUNTIFS($K$5:$K$1252,1,$J$5:$J$1252,"<"&J6)/($N$3-1),"") -> 0.91300746 | M6: =IF(K6=1,COUNTIFS($K$5:$K$1252,1,$E$5:$E$1252,"<"&E6)/($N$3-1),"") -> 0.41342171 | N6: =IF(K6=1,L6-M6,"") -> 0.49958575 | O6: =IF(K6=1,E6,"") -> 7.907726 | P6: =IF(K6=1,J6,"") -> 6.9478261
A7: Cengiz Gonul | B7: Turkey | C7: Forward | D7: 32 | E7: 5.395874 | F7: 1757 | G7: 26 | H7: 9 | I7: 2 | J7: 6.5730769 | K7: =IF(F7>=$N$1,1,0) -> 1 | L7: =IF(K7=1,COUNTIFS($K$5:$K$1252,1,$J$5:$J$1252,"<"&J7)/($N$3-1),"") -> 0.78210439 | M7: =IF(K7=1,COUNTIFS($K$5:$K$1252,1,$E$5:$E$1252,"<"&E7)/($N$3-1),"") -> 0.29660315 | N7: =IF(K7=1,L7-M7,"") -> 0.48550124 | O7: =IF(K7=1,E7,"") -> 5.395874 | P7: =IF(K7=1,J7,"") -> 6.5730769
A8: Victor Ajayi | B8: Nigeria | C8: Forward | D8: 23 | E8: 5.257395 | F8: 1518 | G8: 24 | H8: 6 | I8: 1 | J8: 6.5333333 | K8: =IF(F8>=$N$1,1,0) -> 1 | L8: =IF(K8=1,COUNTIFS($K$5:$K$1252,1,$J$5:$J$1252,"<"&J8)/($N$3-1),"") -> 0.77050539 | M8: =IF(K8=1,COUNTIFS($K$5:$K$1252,1,$E$5:$E$1252,"<"&E8)/($N$3-1),"") -> 0.28997514 | N8: =IF(K8=1,L8-M8,"") -> 0.48053024 | O8: =IF(K8=1,E8,"") -> 5.257395 | P8: =IF(K8=1,J8,"") -> 6.5333333
A9: Nabil Bennacer | B9: Algeria | C9: Midfielder | D9: 24 | E9: 1.834275 | F9: 1417 | G9: 23 | H9: 2 | I9: 1 | J9: 6.2086957 | K9: =IF(F9>=$N$1,1,0) -> 1 | L9: =IF(K9=1,COUNTIFS($K$5:$K$1252,1,$J$5:$J$1252,"<"&J9)/($N$3-1),"") -> 0.50787075 | M9: =IF(K9=1,COUNTIFS($K$5:$K$1252,1,$E$5:$E$1252,"<"&E9)/($N$3-1),"") -> 0.042253521 | N9: =IF(K9=1,L9-M9,"") -> 0.46561723 | O9: =IF(K9=1,E9,"") -> 1.834275 | P9: =IF(K9=1,J9,"") -> 6.2086957
A10: Xherdan Mvogo | B10: Switzerland | C10: Forward | D10: 23 | E10: 1.720821 | F10: 1084 | G10: 18 | H10: 5 | I10: 0 | J10: 6.1944444 | K10: =IF(F10>=$N$1,1,0) -> 1 | L10: =IF(K10=1,COUNTIFS($K$5:$K$1252,1,$J$5:$J$1252,"<"&J10)/($N$3-1),"") -> 0.49212925 | M10: =IF(K10=1,COUNTIFS($K$5:$K$1252,1,$E$5:$E$1252,"<"&E10)/($N$3-1),"") -> 0.031483016 | N10: =IF(K10=1,L10-M10,"") -> 0.46064623 | O10: =IF(K10=1,E10,"") -> 1.720821 | P10: =IF(K10=1,J10,"") -> 6.1944444
A11: Leandro Pezzella | B11: Argentina | C11: Defender | D11: 31 | E11: 2.073221 | F11: 942 | G11: 17 | H11: 1 | I11: 1 | J11: 6.2058824 | K11: =IF(F11>=$N$1,1,0) -> 1 | L11: =IF(K11=1,COUNTIFS($K$5:$K$1252,1,$J$5:$J$1252,"<"&J11)/($N$3-1),"") -> 0.50289975 | M11: =IF(K11=1,COUNTIFS($K$5:$K$1252,1,$E$5:$E$1252,"<"&E11)/($N$3-1),"") -> 0.057166529 | N11: =IF(K11=1,L11-M11,"") -> 0.44573322 | O11: =IF(K11=1,E11,"") -> 2.073221 | P11: =IF(K11=1,J11,"") -> 6.2058824
A12: Ao Mori | B12: Japan | C12: Defender | D12: 25 | E12: 2.700538 | F12: 1097 | G12: 18 | H12: 1 | I12: 1 | J12: 6.25 | K12: =IF(F12>=$N$1,1,0) -> 1 | L12: =IF(K12=1,COUNTIFS($K$5:$K$1252,1,$J$5:$J$1252,"<"&J12)/($N$3-1),"") -> 0.54598177 | M12: =IF(K12=1,COUNTIFS($K$5:$K$1252,1,$E$5:$E$1252,"<"&E12)/($N$3-1),"") -> 0.10190555 | N12: =IF(K12=1,L12-M12,"") -> 0.44407622 | O12: =IF(K12=1,E12,"") -> 2.700538 | P12: =IF(K12=1,J12,"") -> 6.25
A13: Christian Robinson | B13: United States | C13: Defender | D13: 32 | E13: 1.383177 | F13: 1634 | G13: 25 | H13: 1 | I13: 0 | J13: 6.144 | K13: =IF(F13>=$N$1,1,0) -> 1 | L13: =IF(K13=1,COUNTIFS($K$5:$K$1252,1,$J$5:$J$1252,"<"&J13)/($N$3-1),"") -> 0.44573322 | M13: =IF(K13=1,COUNTIFS($K$5:$K$1252,1,$E$5:$E$1252,"<"&E13)/($N$3-1),"") -> 0.018227009 | N13: =IF(K13=1,L13-M13,"") -> 0.42750621 | O13: =IF(K13=1,E13,"") -> 1.383177 | P13: =IF(K13=1,J13,"") -> 6.144
A14: Jan Bednarek | B14: Poland | C14: Defender | D14: 29 | E14: 1.867106 | F14: 1431 | G14: 26 | H14: 1 | I14: 0 | J14: 6.1576923 | K14: =IF(F14>=$N$1,1,0) -> 1 | L14: =IF(K14=1,COUNTIFS($K$5:$K$1252,1,$J$5:$J$1252,"<"&J14)/($N$3-1),"") -> 0.45733223 | M14: =IF(K14=1,COUNTIFS($K$5:$K$1252,1,$E$5:$E$1252,"<"&E14)/($N$3-1),"") -> 0.045567523 | N14: =IF(K14=1,L14-M14,"") -> 0.41176471 | O14: =IF(K14=1,E14,"") -> 1.867106 | P14: =IF(K14=1,J14,"") -> 6.1576923
A15: Duvan Cuadrado | B15: Colombia | C15: Goalkeeper | D15: 32 | E15: 5.548705 | F15: 987 | G15: 13 | H15: 0 | I15: 0 | J15: 6.4230769 | K15: =IF(F15>=$N$1,1,0) -> 1 | L15: =IF(K15=1,COUNTIFS($K$5:$K$1252,1,$J$5:$J$1252,"<"&J15)/($N$3-1),"") -> 0.71748136 | M15: =IF(K15=1,COUNTIFS($K$5:$K$1252,1,$E$5:$E$1252,"<"&E15)/($N$3-1),"") -> 0.30654515 | N15: =IF(K15=1,L15-M15,"") -> 0.41093621 | O15: =IF(K15=1,E15,"") -> 5.548705 | P15: =IF(K15=1,J15,"") -> 6.4230769
A16: Sergino Busio | B16: United States | C16: Defender | D16: 23 | E16: 2.186215 | F16: 1327 | G16: 22 | H16: 1 | I16: 0 | J16: 6.1818182 | K16: =IF(F16>=$N$1,1,0) -> 1 | L16: =IF(K16=1,COUNTIFS($K$5:$K$1252,1,$J$5:$J$1252,"<"&J16)/($N$3-1),"") -> 0.47473074 | M16: =IF(K16=1,COUNTIFS($K$5:$K$1252,1,$E$5:$E$1252,"<"&E16)/($N$3-1),"") -> 0.064623032 | N16: =IF(K16=1,L16-M16,"") -> 0.41010771 | O16: =IF(K16=1,E16,"") -> 2.186215 | P16: =IF(K16=1,J16,"") -> 6.1818182
... A1252: Pedro Gavi | B1252: Spain | C1252: Goalkeeper | D1252: 36 | E1252: 2.084465 | F1252: 814 | G1252: 11 | H1252: 0 | I1252: 0 | J1252: 5.9181818 | K1252: =IF(F1252>=$N$1,1,0) -> 0 | L1252: =IF(K1252=1,COUNTIFS($K$5:$K$1252,1,$J$5:$J$1252,"<"&J1252)/($N$3-1),"") | M1252: =IF(K1252=1,COUNTIFS($K$5:$K$1252,1,$E$5:$E$1252,"<"&E1252)/($N$3-1),"") | N1252: =IF(K1252=1,L1252-M1252,"") | O1252: =IF(K1252=1,E1252,"") | P1252: =IF(K1252=1,J1252,"")

Sheet Positions
A1: Position profile
A2: Raw totals from the data, rates by formula (matches the Position profile table on the Players page)
A4: Position | B4: Players used | C4: Appearances | D4: Rating sum | E4: Minutes | F4: Goals | G4: Assists | H4: Key passes | I4: Defensive actions | J4: Successful passes | K4: Total passes | L4: Distance (km) | M4: Avg rating | N4: G+A per 90 | O4: Key passes per 90 | P4: Def. actions per 90 | Q4: Pass accuracy | R4: Distance per 90 (km)
A5: Goalkeeper | B5: 144 | C5: 2100 | D5: 13031.1 | E5: 160986 | F5: 0 | G5: 52 | H5: 581 | I5: 3491 | J5: 31110 | K5: 44464 | L5: 15188.1 | M5: =D5/C5 -> 6.2052857 | N5: =(F5+G5)*90/E5 -> 0.029070851 | O5: =H5*90/E5 -> 0.32481085 | P5: =I5*90/E5 -> 1.9516604 | Q5: =J5/K5 -> 0.69966715 | R5: =L5*90/E5 -> 8.4909806
A6: Defender | B6: 432 | C6: 11484 | D6: 71626.8 | E6: 708606 | F6: 353 | G6: 452 | H6: 4300 | I6: 85802 | J6: 321895 | K6: 399212 | L6: 75469.9 | M6: =D6/C6 -> 6.2370951 | N6: =(F6+G6)*90/E6 -> 0.102243 | O6: =H6*90/E6 -> 0.54614271 | P6: =I6*90/E6 -> 10.897706 | Q6: =J6/K6 -> 0.80632596 | R6: =L6*90/E6 -> 9.5854269
A7: Midfielder | B7: 384 | C7: 10274 | D7: 64861.2 | E7: 632651 | F7: 866 | G7: 1368 | H7: 13399 | I7: 36329 | J7: 360802 | K7: 430997 | L7: 75582.1 | M7: =D7/C7 -> 6.31314 | N7: =(F7+G7)*90/E7 -> 0.31780555 | O7: =H7*90/E7 -> 1.906122 | P7: =I7*90/E7 -> 5.1681101 | Q7: =J7/K7 -> 0.83713344 | R7: =L7*90/E7 -> 10.752198
A8: Forward | B8: 288 | C8: 7700 | D8: 48935.5 | E8: 474267 | F8: 1805 | G8: 987 | H8: 7482 | I8: 8979 | J8: 130860 | K8: 172408 | L8: 51969 | M8: =D8/C8 -> 6.3552597 | N8: =(F8+G8)*90/E8 -> 0.52982813 | O8: =H8*90/E8 -> 1.4198331 | P8: =I8*90/E8 -> 1.7039136 | Q8: =J8/K8 -> 0.7590135 | R8: =L8*90/E8 -> 9.8619765

Sheet Measures
A1: DAX measures (101)
A2: All measures live in the _Measures table, grouped into display folders
A4: Folder | B4: Measure | C4: Format | D4: Description | E4: DAX
A5: 1 Tournament | B5: Matches | C5: #,0 | D5: Number of matches in the current filter context. | E5: DISTINCTCOUNT ( Fact_TeamMatch[match_id] )
A6: 1 Tournament | B6: Total Goals | C6: #,0 | D6: Official goals from the match score (goals_team). Use this, not player goals, for team/tournament totals. | E6: SUM ( Fact_TeamMatch[goals_for] )
A7: 1 Tournament | B7: Goals per Match | C7: 0.00 | D7: Goals scored per match in the current context (both teams when unfiltered). | E7: DIVIDE ( [Total Goals], [Matches] )
A8: 1 Tournament | B8: Players Used | C8: #,0 | D8: Distinct players with at least one minute on the pitch. | E8: CALCULATE ( DISTINCTCOUNT ( Fact_PlayerMatch[player_id] ), Fact_PlayerMatch[is_appearance] = 1 )
A9: 1 Tournament | B9: Avg Player Rating | C9: 0.00 | D9: Average match rating, appearances only (unused substitutes have rating 0 and are excluded). | E9: CALCULATE ( AVERAGE ( Fact_PlayerMatch[player_rating] ), Fact_PlayerMatch[is_appearance] = 1 )
A10: 1 Tournament | B10: Draw Rate | C10: 0.0% | D10: Share of matches that ended in a draw. | E10: DIVIDE ( CALCULATE ( [Matches], Fact_TeamMatch[result] = "D" ), [Matches] )
A11: 1 Tournament | B11: Data Disclaimer | D11: Text for a card on every page. | E11: "Simulated data - not official FIFA World Cup 2026 results"
A12: 1 Tournament | B12: Top Scorer | D12: Player(s) with the most goals in the current selection. | E12: VAR Best = TOPN ( 1, VALUES ( Dim_Player[Player Label] ), [Goals], DESC ) RETURN CONCATENATEX ( Best, Dim_Player[Player Label], ", " )
A13: 1 Tournament | B13: Top Scorer Goals | C13: #,0 | D13: Goals of the top scorer in the current selection. | E13: MAXX ( VALUES ( Dim_Player[player_id] ), [Goals] )
A14: 1 Tournament | B14: Scorer Rank Value | C14: 0.0000 | D14: Goals, with assists then goals per 90 as tie-breakers. Used by the Top 10 scorers filter so exactly 10 players show. | E14: [Goals] + DIVIDE ( [Assists], 100 ) + DIVIDE ( [Goals per 90], 10000 )
A15: 2 Teams | B15: Team Matches | C15: #,0 | D15: Team-match rows (each match counts once per team). | E15: COUNTROWS ( Fact_TeamMatch )
A16: 2 Teams | B16: Wins | C16: #,0 | E16: CALCULATE ( [Team Matches], Fact_TeamMatch[result] = "W" )
A17: 2 Teams | B17: Draws | C17: #,0 | E17: CALCULATE ( [Team Matches], Fact_TeamMatch[result] = "D" )
A18: 2 Teams | B18: Losses | C18: #,0 | E18: CALCULATE ( [Team Matches], Fact_TeamMatch[result] = "L" )
A19: 2 Teams | B19: Win % | C19: 0.0% | D19: Wins / matches played. Teams played 33-66 matches, so compare rates, not totals. | E19: DIVIDE ( [Wins], [Team Matches] )
A20: 2 Teams | B20: Points | C20: #,0 | D20: 3 for a win, 1 for a draw. | E20: SUM ( Fact_TeamMatch[points] )
A21: 2 Teams | B21: Points per Match | C21: 0.00 | E21: DIVIDE ( [Points], [Team Matches] )
A22: 2 Teams | B22: Goals For | C22: #,0 | E22: SUM ( Fact_TeamMatch[goals_for] )
A23: 2 Teams | B23: Goals Against | C23: #,0 | E23: SUM ( Fact_TeamMatch[goals_against] )
A24: 2 Teams | B24: Goal Difference | C24: +#,0;-#,0;0 | E24: [Goals For] - [Goals Against]
A25: 2 Teams | B25: Goals For per Match | C25: 0.00 | E25: DIVIDE ( [Goals For], [Team Matches] )
A26: 2 Teams | B26: Goals Against per Match | C26: 0.00 | E26: DIVIDE ( [Goals Against], [Team Matches] )
A27: 2 Teams | B27: Team xG | C27: #,0.0 | D27: Sum of player xG in the team's matches. | E27: SUM ( Fact_TeamMatch[xg_for] )
A28: 2 Teams | B28: Team xG Against | C28: #,0.0 | E28: SUM ( Fact_TeamMatch[xg_against] )
A29: 2 Teams | B29: Team xG per Match | C29: 0.00 | E29: DIVIDE ( [Team xG], [Team Matches] )
A30: 2 Teams | B30: Goals minus xG | C30: +#,0.0;-#,0.0;0.0 | D30: Positive = scored more than expected. Note: xG in this dataset is ~3x lower than goals, so use it for ranking, not absolute finishing skill. | E30: [Goals For] - [Team xG]
A31: 2 Teams | B31: Goals to xG Ratio | C31: 0.00 | E31: DIVIDE ( [Goals For], [Team xG] )
A32: 2 Teams | B32: Team Shots per Match | C32: 0.0 | E32: DIVIDE ( SUM ( Fact_TeamMatch[shots_for] ), [Team Matches] )
A33: 2 Teams | B33: Team Clean Sheets | C33: #,0 | D33: Matches where the team conceded 0 (from the match score). | E33: CALCULATE ( [Team Matches], Fact_TeamMatch[goals_against] = 0 )
A34: 2 Teams | B34: Clean Sheet % | C34: 0.0% | E34: DIVIDE ( [Team Clean Sheets], [Team Matches] )
A35: 3 Players | B35: Appearances | C35: #,0 | D35: Matches in which the player played at least one minute. | E35: CALCULATE ( COUNTROWS ( Fact_PlayerMatch ), Fact_PlayerMatch[is_appearance] = 1 )
A36: 3 Players | B36: Minutes Played | C36: #,0 | E36: SUM ( Fact_PlayerMatch[minutes_played] )
A37: 3 Players | B37: Avg Minutes per Appearance | C37: 0 | E37: DIVIDE ( [Minutes Played], [Appearances] )
A38: 3 Players | B38: Goals | C38: #,0 | D38: Goals credited to players. Does not always equal the match score - use [Total Goals] for team totals. | E38: SUM ( Fact_PlayerMatch[goals] )
A39: 3 Players | B39: Assists | C39: #,0 | E39: SUM ( Fact_PlayerMatch[assists] )
A40: 3 Players | B40: Goal Contributions | C40: #,0 | D40: Goals + assists. | E40: [Goals] + [Assists]
A41: 3 Players | B41: Shots | C41: #,0 | E41: SUM ( Fact_PlayerMatch[shots] )
...

Sheet Data Model
A1: Data model
A2: Star schema built in Power Query from one CSV (parameter CsvFilePath)
A4: Table | B4: Type | C4: Rows | D4: Grain / content | E4: Key column
A5: Fact_PlayerMatch | B5: Fact | C5: 54600 | D5: One player in one match: minutes, goals, passes, defending, physical, ratings; is_appearance flag | E5: player_id + match_id
A6: Fact_TeamMatch | B6: Fact | C6: 2100 | D6: One team in one match: official score, result, points, team and opponent xG and shots (self-join) | E6: team + match_id
A7: Dim_Player | B7: Dimension | C7: 1248 | D7: Name, label, age, age group, position, club, height, foot, market value, value band | E7: player_id
A8: Dim_Team | B8: Dimension | C8: 48 | D8: Team, FIFA code, confederation | E8: team
A9: Dim_Match | B9: Dimension | C9: 1050 | D9: Date, stadium, stage (with Stage Order), fixture, score label | E9: match_id
A10: Dim_Stadium | B10: Dimension | C10: 16 | D10: City, country, latitude, longitude | E10: stadium
A11: Dim_Date | B11: Dimension (date table) | C11: 61 | D11: Calendar 1 Jun – 31 Jul 2026 | E11: Date
A12: Compare_Player_A / _B | B12: Helper (disconnected) | C12: 1248 | D12: Player lists for the two comparison slicers | E12: player_id
A13: Comparison_Metrics | B13: Helper (disconnected) | C13: 24 | D13: Metric list with category, display format and direction | E13: Metric
A14: Param_MinMinutes | B14: Helper (disconnected) | C14: 21 | D14: Minimum-minutes values 0–3000 in steps of 150 | E14: Min Minutes
A15: _Measures | B15: Measure table | C15: 0 | D15: 101 DAX measures
A18: Relationships (all many-to-one, single direction)
A19: From (many) | B19: To (one) | D19: Why
A20: Fact_PlayerMatch[player_id] | B20: Dim_Player[player_id] | D20: Player attributes
A21: Fact_PlayerMatch[team] | B21: Dim_Team[team] | D21: Team filters player rows directly
A22: Fact_PlayerMatch[match_id] | B22: Dim_Match[match_id] | D22: Stage and fixture
A23: Fact_PlayerMatch[match_date] | B23: Dim_Date[Date] | D23: Calendar
A24: Fact_PlayerMatch[stadium] | B24: Dim_Stadium[stadium] | D24: Venue
A25: Fact_TeamMatch[team] | B25: Dim_Team[team] | D25: Team results
A26: Fact_TeamMatch[match_id] | B26: Dim_Match[match_id] | D26: Stage and fixture
A27: Fact_TeamMatch[match_date] | B27: Dim_Date[Date] | D27: Calendar
A28: Fact_TeamMatch[stadium] | B28: Dim_Stadium[stadium] | D28: Venue
A30: Design notes
A31: • Two fact tables because results live at team-match grain; deriving them from player rows would repeat each score 26 times.
A32: • No relationship between Dim_Team and Dim_Player: it would create a second filter path from team to Fact_PlayerMatch (ambiguity).
A33: • Comparison tables are disconnected on purpose; measures apply the selection with TREATAS.
A34: • Auto date/time is off; all fact columns are hidden so users work with measures only.

Sheet Data Quality
A1: Data quality findings
A2: Profiled in Python before modelling. The file has no missing values, but these issues would have produced wrong numbers.
A4: # | B4: Issue | C4: Evidence | D4: Decision in the model
A5: 1 | B5: Unused substitutes in the data | C5: 23,042 rows (42%) with 0 minutes; rating 0 but stamina still filled | D5: is_appearance flag; averages and appearances use players who played only
A6: 2 | B6: Team score ≠ sum of player goals | C6: Match in 575 of 2,100 team-matches (27%); 3,024 player goals vs 2,794 match goals | D6: Team/tournament goals from the match score; player goals from player rows
A7: 3 | B7: pass_accuracy inconsistent | C7: Equals successful/total passes in 22% of rows | D7: Dropped; Pass Accuracy % recalculated from summed passes
A8: 4 | B8: save_percentage inconsistent | C8: Matches its formula in 6% of goalkeeper rows | D8: Dropped; Save % = saves / (saves + goals conceded)
A9: 5 | B9: Tournament total columns unstable | C9: total_* and tournament_rating differ between rows of the same player (1,102 players); player_of_match_awards for 666 players | D9: Excluded; totals calculated in DAX
A10: 6 | B10: xG on a different scale | C10: Goals = 3.18 × xG | D10: xG used for relative comparison only
A11: 7 | B11: Uneven matches per team | C11: 33 to 66 matches per team | D11: Teams compared with per-match rates
A12: 8 | B12: Unrealistic tournament structure | C12: 1,050 matches; Final dated 15 Jun–30 Jul; 119 knockout draws, no penalty data | D12: Shown as recorded; stages ordered by Stage Order; data labelled as simulated
A13: 9 | B13: Duplicate names | C13: 3 pairs of team-mates share a name | D13: Player Label adds the shirt number to duplicates
A14: 10 | B14: Goalkeeper columns slightly off | C14: goals_conceded matches the score in 94.5%; clean_sheet in 98.4% | D14: Team clean sheets from the score; GK metrics from GK columns

Sheet QA Reconciliation
A1: QA reconciliation
A2: Every number visible in the dashboard screenshots recalculated independently in Python (pandas)
A3: Checks passed | B3: =COUNTIF(E6:E102,"OK")&" of "&COUNTA(E6:E102) -> 97 of 97
A5: Page | B5: Check | C5: Power BI (DAX) | D5: Python (pandas) | E5: Result
A6: Overview | B6: Matches | C6: 1,050 | D6: 1,050 | E6: OK
A7: Overview | B7: Total Goals | C7: 2,794 | D7: 2,794 | E7: OK
A8: Overview | B8: Goals per Match | C8: 2.66 | D8: 2.66 | E8: OK
A9: Overview | B9: Players Used | C9: 1,248 | D9: 1,248 | E9: OK
A10: Overview | B10: Avg Player Rating | C10: 6.29 | D10: 6.29 | E10: OK
A11: Overview | B11: Draw Rate | C11: 26.3% | D11: 26.3% | E11: OK
A12: Overview | B12: Goals per match - Group Stage | C12: 2.66 | D12: 2.66 | E12: OK
A13: Overview | B13: Goals per match - Round of 32 | C13: 2.69 | D13: 2.69 | E13: OK
A14: Overview | B14: Goals per match - Round of 16 | C14: 2.73 | D14: 2.73 | E14: OK
A15: Overview | B15: Goals per match - Quarter Finals | C15: 2.38 | D15: 2.38 | E15: OK
A16: Overview | B16: Goals per match - Semi Finals | C16: 3.00 | D16: 3.00 | E16: OK
... A102: Player Profile | B102: Info line | C102: Australia | Forward | Age 23 | Ulsan HD | 185 cm | Right foot | D102: Australia | Forward | Age 23 | Ulsan HD | 185 cm | Right foot | E102: OK
